<?xml version="1.0" ?>
<!-- =================================================================================== -->
<!-- |    This document was autogenerated by xacro from ./robots/prise4.xacro          | -->
<!-- |    EDITING THIS FILE BY HAND IS NOT RECOMMENDED                                 | -->
<!-- =================================================================================== -->
<!-- Revolute-Revolute Manipulator -->
<robot name="prise3" xmlns:xacro="http://www.ros.org/wiki/xacro">
  <link name="world"/>
  <link name="base_link">
    <inertial>
      <origin rpy="0 0 0" xyz="0 0 0"/>
      <mass value="54"/>
 
                    <inertia
        ixx="76.8709047512236"
        ixy="-0.317641732156655"
        ixz="-2.72714300565647"
        iyy="59.4673166498106"
        iyz="2.93869533447697"
        izz="54.3371716853488" />
   
    </inertial>
    <visual>
      <origin rpy="0 0 0" xyz="0 0 0"/>
      <geometry>
        <mesh filename="package://prise3_gazebo/meshes/base_linkv2.stl"/>
      </geometry>
      <material name="">
        <color rgba="0.25 0.25 0.16 1"/>
      </material>
    </visual>
  </link>

 <joint name="fixed" type="fixed">
    <parent link="world"/>
    <child link="base_link"/>
  </joint> 


 <link name="axe_x_link">
   <inertial>
      <origin xyz="0 0 2.27436746463313"  rpy="0 0 0" />
      <mass  value="1.24718562315346" />
      <inertia  ixx="0.00553600382926194" ixy="4.16135471249498E-07"  ixz="-2.6765103577275E-06"
        iyy="0.528726480355761" iyz="0.00063946667879318"  izz="0.527869777651479"/>
    </inertial>
    <visual>
      <origin rpy="0 0 0" xyz="0 0 0"/>
      <geometry>
        <mesh filename="package://prise3_gazebo/meshes/axe_xv2.stl"/>
      </geometry>
      <material name="">
        <color rgba="0.32 0.32 0.32 1"/>
      </material>
    </visual>
  
  </link>
  <joint name="axe_x_joint" type="prismatic">
    <origin rpy="0 0 0" xyz="0 -0.86 2.278"/>
    <parent link="base_link"/>
    <child link="axe_x_link"/>
    <axis xyz="0 1 0"/>
    <limit effort="10" lower="0" upper="1.6" velocity="0.3"/>
    <dynamics damping="10" friction="10">     </dynamics>
  </joint>

<link name="axe_y_link">
   <inertial>
      <origin xyz="-0.99969 1.1548 2.2822" rpy="0 0 0" />
      <mass value="0.083823" />
      <inertia 
        ixx="0.0047427"
        ixy="1.1132E-06"
        ixz="-2.7484E-06"
        iyy="0.0077894"
        iyz="-0.00042131"
        izz="0.0042694" />
    </inertial>
    <visual>
      <origin rpy="0 0 0" xyz="0 0 0"/>
      <geometry>
        <mesh filename="package://prise3_gazebo/meshes/axeYv2.stl"/>
      </geometry>
      <material name="">
        <color rgba="0.32 0.32 0.32 1"/>
      </material>
    </visual>
  
  </link>

 <joint name="axe_y_joint" type="prismatic">
    <origin rpy="0 0 0" xyz="-0.5 0.098 -0.025"/>
    <parent link="axe_x_link"/>
    <child link="axe_y_link"/>
    <axis xyz="1 0 0"/>
    <limit effort="10" lower="0" upper="1.0" velocity="0.3"/>
    <dynamics damping="10" friction="10">     </dynamics>
  </joint>



<link name="axe_z_link">
    <inertial>
      <origin xyz="-0.99969 1.1548 2.2822" rpy="0 0 0" />
      <mass value="0.83823" />
      <inertia
        ixx="76.8709047512236"
        ixy="-0.317641732156655"
        ixz="-2.72714300565647"
        iyy="59.4673166498106"
        iyz="2.93869533447697"
        izz="54.3371716853488" />
	</inertial>
   
    <visual>
      <origin xyz="0 0 0" rpy="0 0 0" />
      <geometry>
        <mesh filename="package://prise3_gazebo/meshes/axeZv2.stl" />
      </geometry>
      <material
        name="">
        <color   rgba="0 0 0.8 1" />
      </material>
    </visual>
  
  </link>

  <joint name="axe_z_joint" type="prismatic">
    <parent link="axe_y_link" />
    <child link="axe_z_link" />
     <origin xyz="0 0.08 -0.5" rpy="0 0 0" />
    <axis xyz="0 0 1" />
    <limit lower="0" upper="1" effort="100" velocity="0.3" />
	<dynamics damping="100" >     </dynamics>
  </joint>

<!-- poignet-->

  <link name="rotation_link">
    <inertial>
      <origin xyz="0 0 0" rpy="0 0 0" />
      <mass value="0.83823" />
      <inertia 
        ixx="0.0047427"
        ixy="1.1132E-06"
        ixz="-2.7484E-06"
        iyy="0.0077894"
        iyz="-0.00042131"
        izz="0.0042694" />
    </inertial>
    <visual>
        <origin xyz="0 0 0" rpy="0 0 0" />
      <geometry>
        <mesh filename="package://prise3_gazebo/meshes/rota.stl" />
      </geometry>
      <material
        name="">
        <color   rgba="0 0 0.8 1" />
      </material>
    </visual>
  </link>


  <joint name="rotation_joint" type="revolute">
    <parent link="axe_z_link" />
    <child link="rotation_link" />
	<origin xyz="0 0 -0.68" rpy="0 0 0" />
    	<axis xyz="0 0 1" />
	<limit effort="10" lower="0" upper="1.57" velocity="0.5"/>

  </joint>

<!-- laser-->


  <link name="laser_link">
 <inertial>
      
      <mass value="0.083823" />
      <inertia 
        ixx="0.47427"
        ixy="1.1132E-06"
        ixz="-2.7484E-06"
        iyy="0.0077894"
        iyz="-0.00042131"
        izz="0.0042694" />
    </inertial>
    <visual>
     <origin xyz="0 0 0" rpy="0 0 0" />
      <geometry>
        <mesh filename="package://prise3_gazebo/meshes/laser.stl" />
      </geometry>
      <material
        name="">
        <color   rgba="0 0 0.8 1" />
      </material>
    </visual>
    
  </link>


  <joint name="laser_joint" type="revolute">
    <parent link="rotation_link" />
    <child link="laser_link" />
  
	<origin xyz="0 0 -0.1" rpy="0 0.20 1.57" />
    	<axis xyz="0 1 0" />
        <limit effort="100" lower="0" upper="1.57" velocity="0.1"/>
	<dynamics damping="01" >     </dynamics>
  </joint>


  <!-- Hokuyo Laser -->
  <link name="hokuyo_link">
    <visual>
      <origin xyz="0 0 0" rpy="0 0 0"/>
      <geometry>
        <mesh filename="package://prise3_gazebo/meshes/hokuyo.dae"/>
      </geometry>
    </visual>

    <inertial>
      <mass value="0.01" />
      <origin xyz="0 0 0" rpy="0 0 0"/>
      <inertia ixx="1e-6" ixy="0" ixz="0" iyy="1e-6" iyz="0" izz="1e-6" />
    </inertial>
  </link>


<joint name="hokuyo_joint" type="fixed">
    <axis xyz="0 1 0" />
    <origin xyz=" 0.28 0 0" rpy="0 -0.2 0"/>
    <parent link="laser_link"/>
    <child link="hokuyo_link"/>
  </joint>


<gazebo>
  <plugin name="gazebo_ros_control" filename="libgazebo_ros_control.so">
    <robotNamespace>/prise3</robotNamespace>
  </plugin>
</gazebo>

<transmission name="trans_x">
  <type>transmission_interface/SimpleTransmission</type>
  <joint name="axe_x_joint">
    <hardwareInterface>EffortJointInterface</hardwareInterface>
  </joint>
  <actuator name="xmotor">
    <mechanicalReduction>2</mechanicalReduction>
    <hardwareInterface>EffortJointInterface</hardwareInterface>
  </actuator>
</transmission>


<transmission name="trans_y">
  <type>transmission_interface/SimpleTransmission</type>
  <joint name="axe_y_joint">
    <hardwareInterface>EffortJointInterface</hardwareInterface>
  </joint>
  <actuator name="ymotor">
    <mechanicalReduction>4</mechanicalReduction>
    <hardwareInterface>EffortJointInterface</hardwareInterface>
  </actuator>
</transmission>



<transmission name="trans_z">
  <type>transmission_interface/SimpleTransmission</type>
  <joint name="axe_z_joint">
    <hardwareInterface>EffortJointInterface</hardwareInterface>
  </joint>
  <actuator name="zmotor">
    <mechanicalReduction>4</mechanicalReduction>
    <hardwareInterface>EffortJointInterface</hardwareInterface>
  </actuator>
</transmission>



<transmission name="rotation_z">
  <type>transmission_interface/SimpleTransmission</type>
  <joint name="rotation_joint">
    <hardwareInterface>EffortJointInterface</hardwareInterface>
  </joint>
  <actuator name="rot_motor">
    <mechanicalReduction>1</mechanicalReduction>
    <hardwareInterface>EffortJointInterface</hardwareInterface>
  </actuator>
</transmission>



<transmission name="rotation_laser">
  <type>transmission_interface/SimpleTransmission</type>
  <joint name="laser_joint">
    <hardwareInterface>EffortJointInterface</hardwareInterface>
  </joint>
  <actuator name="rot_laser_motor">
    <mechanicalReduction>1</mechanicalReduction>
    <hardwareInterface>EffortJointInterface</hardwareInterface>
  </actuator>
</transmission>

 <!-- hokuyo -->
  <gazebo reference="hokuyo_link">
    <sensor type="gpu_ray" name="head_hokuyo_sensor">
      <pose>0 0 0 0 0 0</pose>
      <visualize>false</visualize>
      <update_rate>40</update_rate>
      <ray>
         <scan>
          <horizontal>
            <samples>720</samples>
            <resolution>1</resolution>
            <min_angle>-0.470796</min_angle>
            <max_angle>0.470796</max_angle>
          </horizontal>
        </scan>
        <range>
          <min>0.015</min>
          <max>0.92</max>
          <resolution>0.001</resolution>
        </range>
        <noise>
          <type>gaussian</type>
          <!-- Noise parameters based on published spec for Hokuyo laser
               achieving "+-30mm" accuracy at range < 10m.  A mean of 0.0m and
               stddev of 0.01m will put 99.7% of samples within 0.03m of the true
               reading. -->
          <mean>0.0</mean>
          <stddev>0.01</stddev>
        </noise>
      </ray>
      <plugin name="gazebo_ros_head_hokuyo_controller" filename="libgazebo_ros_gpu_laser.so">
        <topicName>/prise3/laser/scan</topicName>
        <frameName>hokuyo_link</frameName>
      </plugin>
    </sensor>
  </gazebo>





</robot>

